Traceback (most recent call last):
  File "/home/ubuntu/pyenvs/fidelity/lib/python3.10/site-packages/matplotlib/style/core.py", line 137, in use
    style = _rc_params_in_file(style)
  File "/home/ubuntu/pyenvs/fidelity/lib/python3.10/site-packages/matplotlib/__init__.py", line 866, in _rc_params_in_file
    with _open_file_or_url(fname) as fd:
  File "/usr/lib/python3.10/contextlib.py", line 135, in __enter__
    return next(self.gen)
  File "/home/ubuntu/pyenvs/fidelity/lib/python3.10/site-packages/matplotlib/__init__.py", line 843, in _open_file_or_url
    with open(fname, encoding='utf-8') as f:
FileNotFoundError: [Errno 2] No such file or directory: '/plots/plot_style.mplstyle'

The above exception was the direct cause of the following exception:

Traceback (most recent call last):
  File "/home/ubuntu/FidelityLandscape/variance/var_shape.py", line 15, in <module>
    plt.style.use(directory.parent / "/plots/plot_style.mplstyle")
  File "/home/ubuntu/pyenvs/fidelity/lib/python3.10/site-packages/matplotlib/style/core.py", line 139, in use
    raise OSError(
OSError: PosixPath('/plots/plot_style.mplstyle') is not a valid package style, path of style file, URL of style file, or library style name (library styles are listed in `style.available`)
simulating
